Workbook

Sheet Concentrado
A1: Año | B1: Entidad Federativa | C1: Tasa de mortalidad por accidentes de tráfico de vehículo de motor en hombres | D1: Tasa de mortalidad por accidentes de tráfico de vehículo de motor en mujeres | E1: Tasa de mortalidad por accidentes de tráfico de vehículo de motor | F1: Tasa de mortalidad por tumor maligno del cuello del útero en mujeres mayores de 25 años | G1: Tasa de mortalidad por tumor maligno de la mama en mujeres mayores de 25 años | H1: Tasa de mortalidad por tumor maligno del colon y recto en hombres | I1: Tasa de mortalidad por tumor maligno del colon y recto en mujeres | J1: Tasa de mortalidad por tumor maligno del colon y recto | K1: Tasa de mortalidad por tumor maligno de tráquea, bronquios y pulmón en hombres | L1: Tasa de mortalidad por tumor maligno de tráquea, bronquios y pulmón en mujeres | M1: Tasa de mortalidad por tumor maligno de tráquea, bronquios y pulmón | N1: Tasa de mortalidad por tumor maligno de la próstata en hombres mayores de 45 años | O1: Tasa de mortalidad por causas externas de morbilidad y mortalidad en hombres | P1: Tasa de mortalidad por causas externas de morbilidad y mortalidad en mujeres | Q1: Tasa de mortalidad por causas externas de morbilidad y mortalidad | R1: Tasa de mortalidad por diabetes mellitus en hombres | S1: Tasa de mortalidad por diabetes mellitus en mujeres | T1: Tasa de mortalidad por diabetes mellitus | U1: Tasa de mortalidad por enfermedades hipertensivas en hombres | V1: Tasa de mortalidad por enfermedades hipertensivas en mujeres | W1: Tasa de mortalidad por enfermedades hipertensivas | X1: Tasa de mortalidad por agresiones (homicidios) en hombres | Y1: Tasa de mortalidad por agresiones (homicidios) en mujeres | Z1: Tasa de mortalidad por agresiones (homicidios) | AA1: Tasa de mortalidad por enfermedades isquémicas del corazón en hombres | AB1: Tasa de mortalidad por enfermedades isquémicas del corazón en mujeres | AC1: Tasa de mortalidad por enfermedades isquémicas del corazón | AD1: Tasa de mortalidad por enfermedades no transmisibles en hombres | AE1: Tasa de mortalidad por enfermedades no transmisibles en mujeres | AF1: Tasa de mortalidad por enfermedades no transmisibles | AG1: Tasa de mortalidad por tumor maligno de la próstata | AH1: Tasa de mortalidad por lesiones autoinfligidas intencionalmente (suicidios) en hombres de 10 a 29 años | AI1: Tasa de mortalidad por lesiones autoinfligidas intencionalmente (suicidios) en mujeres de 10 a 29 años | AJ1: Tasa de mortalidad por lesiones autoinfligidas intencionalmente (suicidios) de 10 a 29 años | AK1: Tasa de mortalidad por lesiones autoinfligidas intencionalmente (suicidios) en hombres | AL1: Tasa de mortalidad por lesiones autoinfligidas intencionalmente (suicidios) en mujeres | AM1: Tasa de mortalidad por lesiones autoinfligidas intencionalmente (suicidios) | AN1: Tasa de mortalidad por enfermedades transmisibles, maternas, perinatales y nutricionales en hombres | AO1: Tasa de mortalidad por enfermedades transmisibles, maternas, perinatales y nutricionales en mujeres | AP1: Tasa de mortalidad por enfermedades transmisibles, maternas, perinatales y nutricionales | AQ1: Tasa de mortalidad por tuberculosis en hombres | AR1: Tasa de mortalidad por tuberculosis en mujeres | AS1: Tasa de mortalidad por tuberculosis | AT1: Tasa de mortalidad por VIH/SIDA en hombres | AU1: Tasa de mortalidad por VIH/SIDA en mujeres | AV1: Tasa de mortalidad por VIH/SIDA | AW1: Tasa de mortalidad por cada 100,000 habitantes en hombres | AX1: Tasa de mortalidad por cada 100,000 habitantes en mujeres | AY1: Tasa de mortalidad por cada 100,000 habitantes | AZ1: Tasa de mortalidad por cada 1000 habitantes en hombres | BA1: Tasa de mortalidad por cada 1000 habitantes en mujeres | BB1: Tasa de mortalidad por cada 1000 habitantes | BC1: Tasa de mortalidad en niños menores de 5 años por enfermedades respiratorias agudas (defunciones por cada 100 mil menores de 5 años) | BD1: Tasa de mortalidad en niños menores de 5 años por enfermedades diarreicas (defunciones por cada 100 mil menores de 5 años) | BE1: Tasa de mortalidad infantil | BF1: Tasa de mortalidad infantil (menores de 5 años) | BG1: Razón de mortalidad materna (defunciones por cada 100 mil nacidos vivos) | BH1: Tasa de mortalidad Neonatal
A2: 1998 | B2: Nacional | C2: 17.305 | D2: 4.525 | E2: 10.837 | F2: 20.354 | G2: 15.094 | H2: 2.43 | I2: 2.44 | J2: 2.435 | K2: 8.795 | L2: 4.008 | M2: 6.372 | N2: 43.754 | O2: 93.622 | P2: 21.428 | Q2: 57.109 | R2: 38.865 | S2: 47.274 | T2: 43.124 | U2: 7.472 | V2: 11.218 | W2: 9.369 | X2: 25.112 | Y2: 3.103 | Z2: 13.98 | AA2: 49.045 | AB2: 39 | AC2: 43.962 | AD2: 330.837 | AE2: 297.697 | AF2: 314.141 | AG2: 7.384 | AH2: 7.2967508 | AI2: 1.7131063 | AJ2: 4.4716963 | AK2: 5.854 | AL2: 1.049 | AM2: 3.42 | AN2: 85.654 | AO2: 70.737 | AP2: 78.126 | AQ2: 5.798 | AR2: 3.125 | AS2: 4.445 | AT2: 7.256 | AU2: 1.253 | AV2: 4.217 | AW2: 518.037 | AX2: 397.349 | AY2: 457.097 | AZ2: 5.18 | BA2: 3.973 | BB2: 4.571 | BC2: 60.373 | BD2: 37.581 | BE2: 23.768 | BF2: 27.961 | BG2: 76.355 | BH2: 10.381644
A3: 1998 | B3: Aguascalientes | C3: 16.236 | D3: 3.788 | E3: 9.882 | F3: 14.174 | G3: 16.618 | H3: 1.975 | I3: 2.315 | J3: 2.148 | K3: 10.97 | L3: 6.944 | M3: 8.915 | N3: 48.853 | O3: 64.942 | P3: 19.149 | Q3: 41.568 | R3: 43.002 | S3: 46.716 | T3: 44.898 | U3: 5.046 | V3: 9.89 | W3: 7.519 | X3: 6.143 | Y3: 2.315 | Z3: 4.189 | AA3: 40.15 | AB3: 28.198 | AC3: 34.049 | AD3: 311.11 | AE3: 280.503 | AF3: 295.487 | AG3: 7.46 | AH3: 4.3962324 | AI3: 1.051055 | AJ3: 2.6863017 | AK3: 3.73 | AL3: 0.631 | AM3: 2.148 | AN3: 73.499 | AO3: 59.552 | AP3: 66.38 | AQ3: 4.827 | AR3: 1.052 | AS3: 2.9 | AT3: 4.388 | AU3: 0.631 | AV3: 2.47 | AW3: 452.842 | AX3: 361.729 | AY3: 406.335 | AZ3: 4.528 | BA3: 3.617 | BB3: 4.063 | BC3: 18.94 | BD3: 22.885 | BE3: 19.727 | BF3: 22.164 | BG3: 34.099 | BH3: 10.608472
A4: 1998 | B4: Baja California | C4: 13.52 | D4: 3.809 | E4: 8.739 | F4: 18.545 | G4: 13.674 | H4: 2.771 | I4: 3.117 | J4: 2.941 | K4: 12.513 | L4: 6.06 | M4: 9.336 | N4: 50.339 | O4: 135.624 | P4: 27.445 | Q4: 82.444 | R4: 43.248 | S4: 40.258 | T4: 41.776 | U4: 6.886 | V4: 7.705 | W4: 7.289 | X4: 41.065 | Y4: 5.021 | Z4: 23.318 | AA4: 68.946 | AB4: 43.548 | AC4: 56.44 | AD4: 347.667 | AE4: 267.347 | AF4: 308.162 | AG4: 7.474 | AH4: 8.5780699 | AI4: 0.87067438 | AJ4: 4.8006298 | AK4: 7.894 | AL4: 0.606 | AM4: 4.305 | AN4: 84.23 | AO4: 53.504 | AP4: 69.101 | AQ4: 13.94 | AR4: 3.376 | AS4: 8.739 | AT4: 14.024 | AU4: 3.463 | AV4: 8.824 | AW4: 573.147 | AX4: 353.144 | AY4: 465.077 | AZ4: 5.731 | BA4: 3.531 | BB4: 4.651 | BC4: 33.443 | BD4: 11.496 | BE4: 14.944 | BF4: 16.243 | BG4: 44.69 | BH4: 10.347376
A5: 1998 | B5: Baja California Sur | C5: 21.775 | D5: 8.483 | E5: 15.304 | F5: 16.272 | G5: 6.509 | H5: 0.947 | I5: 5.489 | J5: 3.158 | K5: 22.722 | L5: 3.493 | M5: 13.361 | N5: 47.625 | O5: 79.528 | P5: 22.455 | Q5: 51.743 | R5: 31.243 | S5: 36.925 | T5: 34.009 | U5: 9.468 | V5: 11.477 | W5: 10.446 | X5: 6.154 | Y5: 1.996 | Z5: 4.13 | AA5: 50.652 | AB5: 37.923 | AC5: 44.455 | AD5: 299.176 | AE5: 234.026 | AF5: 267.459 | AG5: 7.574 | AH5: 12.983794 | AI5: 2.4877478 | AJ5: 7.8733004 | AK5: 14.201 | AL5: 1.497 | AM5: 8.016 | AN5: 58.226 | AO5: 50.897 | AP5: 54.658 | AQ5: 6.627 | AR5: 2.994 | AS5: 4.858 | AT5: 7.101 | AU5: 1.996 | AV5: 4.616 | AW5: 439.296 | AX5: 311.868 | AY5: 377.26 | AZ5: 4.393 | BA5: 3.119 | BB5: 3.773 | BC5: 18.666 | BD5: 16.592 | BE5: 17.192 | BF5: 18.933 | BG5: 71.254 | BH5: 7.9397394
A6: 1998 | B6: Campeche | C6: 20.08 | D6: 3.252 | E6: 11.732 | F6: 26.901 | G6: 8.967 | H6: 1.746 | I6: 1.774 | J6: 1.76 | K6: 7.566 | L6: 2.365 | M6: 4.986 | N6: 37.208 | O6: 98.072 | P6: 16.258 | Q6: 57.485 | R6: 25.609 | S6: 33.404 | T6: 29.476 | U6: 1.746 | V6: 4.139 | W6: 2.933 | X6: 22.117 | Y6: 2.365 | Z6: 12.318 | AA6: 44.525 | AB6: 34.882 | AC6: 39.741 | AD6: 285.194 | AE6: 232.939 | AF6: 259.271 | AG6: 6.111 | AH6: 16.703341 | AI6: 4.3403092 | AJ6: 10.509683 | AK6: 14.26 | AL6: 2.956 | AM6: 8.652 | AN6: 74.209 | AO6: 53.505 | AP6: 63.938 | AQ6: 4.947 | AR6: 0.887 | AS6: 2.933 | AT6: 5.529 | AU6: 2.069 | AV6: 3.813 | AW6: 474.935 | AX6: 318.37 | AY6: 397.265 | AZ6: 4.749 | BA6: 3.184 | BB6: 3.973 | BC6: 33.379 | BD6: 36.955 | BE6: 28.115 | BF6: 33.214 | BG6: 60.5 | BH6: 9.8614556
A7: 1998 | B7: Coahuila | C7: 13.022 | D7: 3.41 | E7: 8.217 | F7: 18.932 | G7: 23.993 | H7: 3.583 | I7: 3.06 | J7: 3.322 | K7: 13.808 | L7: 5.333 | M7: 9.572 | N7: 50.623 | O7: 73.499 | P7: 18.71 | Q7: 46.11 | R7: 48.242 | S7: 67.145 | T7: 57.692 | U7: 9.264 | V7: 13.114 | W7: 11.189 | X7: 10.225 | Y7: 1.923 | Z7: 6.075 | AA7: 68.168 | AB7: 50.883 | AC7: 59.527 | AD7: 355.785 | AE7: 328.906 | AF7: 342.436 | AG7: 8.74 | AH7: 9.0598925 | AI7: 2.237562 | AJ7: 5.670075 | AK7: 6.292 | AL7: 1.137 | AM7: 3.715 | AN7: 56.982 | AO7: 48.61 | AP7: 52.797 | AQ7: 7.953 | AR7: 3.322 | AS7: 5.638 | AT7: 4.807 | AU7: 0.525 | AV7: 2.666 | AW7: 490.723 | AX7: 400.86 | AY7: 445.888 | AZ7: 4.907 | BA7: 4.009 | BB7: 4.459 | BC7: 26.084 | BD7: 19.925 | BE7: 18.788 | BF7: 21.234 | BG7: 72.309 | BH7: 6.331458
A8: 1998 | B8: Colima | C8: 14.07 | D8: 6.057 | E8: 10.054 | F8: 29.63 | G8: 24.692 | H8: 1.521 | I8: 3.407 | J8: 2.466 | K8: 11.028 | L8: 5.678 | M8: 8.347 | N8: 54.137 | O8: 73.01 | P8: 29.526 | Q8: 51.408 | R8: 41.068 | S8: 49.588 | T8: 45.338 | U8: 6.464 | V8: 12.492 | W8: 9.485 | X8: 17.872 | Y8: 5.299 | Z8: 11.761 | AA8: 57.42 | AB8: 42.775 | AC8: 50.08 | AD8: 347.56 | AE8: 311.913 | AF8: 329.886 | AG8: 9.507 | AH8: 6.7241098 | AI8: 2.8429821 | AJ8: 4.7704006 | AK8: 7.605 | AL8: 1.893 | AM8: 4.742 | AN8: 77.574 | AO8: 53.752 | AP8: 65.636 | AQ8: 7.225 | AR8: 2.65 | AS8: 4.932 | AT8: 8.746 | AU8: 1.893 | AV8: 5.312 | AW8: 500.806 | AX8: 397.841 | AY8: 449.586 | AZ8: 5.008 | BA8: 3.978 | BB8: 4.496 | BC8: 21.195 | BD8: 11.413 | BE8: 22.107 | BF8: 25.244 | BG8: 32.056 | BH8: 9.0559385
A9: 1998 | B9: Chiapas | C9: 13.931 | D9: 3.488 | E9: 8.713 | F9: 27.111 | G9: 7.22 | H9: 1.507 | I9: 1.874 | J9: 1.691 | K9: 3.743 | L9: 2.238 | M9: 2.991 | N9: 25.36 | O9: 115.348 | P9: 24.777 | Q9: 70.172 | R9: 16.53 | S9: 28.369 | T9: 22.446 | U9: 5.042 | V9: 5.83 | W9: 5.436 | X9: 37.271 | Y9: 5.361 | Z9: 21.327 | AA9: 26.459 | AB9: 21.342 | AC9: 23.902 | AD9: 236.935 | AE9: 215.708 | AF9: 226.433 | AG9: 3.691 | AH9: 4.4685434 | AI9: 0.87448624 | AJ9: 2.6519789 | AK9: 3.899 | AL9: 0.781 | AM9: 2.341 | AN9: 117.844 | AO9: 101.503 | AP9: 109.679 | AQ9: 11.8 | AR9: 7.235 | AS9: 9.519 | AT9: 4.003 | AU9: 1.197 | AV9: 2.601 | AW9: 492.063 | AX9: 361.248 | AY9: 426.882 | AZ9: 4.921 | BA9: 3.612 | BB9: 4.269 | BC9: 126.189 | BD9: 118.166 | BE9: 32.587 | BF9: 39.727 | BG9: 99.652 | BH9: 8.3903515
A10: 1998 | B10: Chihuahua | C10: 9.268 | D10: 3.154 | E10: 6.221 | F10: 19.09 | G10: 20.239 | H10: 3.267 | I10: 2.684 | J10: 2.977 | K10: 13.868 | L10: 7.046 | M10: 10.468 | N10: 42.175 | O10: 131.949 | P10: 31.606 | Q10: 82.006 | R10: 34.804 | S10: 50.127 | T10: 42.441 | U10: 10.335 | V10: 14.562 | W10: 12.441 | X10: 36.071 | Y10: 4.966 | Z10: 20.602 | AA10: 79.609 | AB10: 51.805 | AC10: 65.752 | AD10: 377.977 | AE10: 328.947 | AF10: 353.608 | AG10: 7.134 | AH10: 15.873954 | AI10: 2.7722621 | AJ10: 9.4072492 | AK10: 12.201 | AL10: 1.812 | AM10: 7.023 | AN10: 82.41 | AO10: 56.099 | AP10: 69.397 | AQ10: 7.668 | AR10: 3.154 | AS10: 5.418 | AT10: 5.534 | AU10: 0.671 | AV10: 3.11 | AW10: 603.27 | AX10: 424.839 | AY10: 514.576 | AZ10: 6.033 | BA10: 4.248 | BB10: 5.146 | BC10: 37.202 | BD10: 16.81 | BE10: 16.925 | BF10: 18.908 | BG10: 44.891 | BH10: 10.950593
A11: 1998 | B11: CDMX | C11: 13.983 | D11: 5.01 | E11: 9.338 | F11: 15.649 | G11: 21.671 | H11: 4.326 | I11: 3.964 | J11: 4.138 | K11: 8.916 | L11: 5.3 | M11: 7.044 | N11: 57.747 | O11: 80.192 | P11: 22.512 | Q11: 50.331 | R11: 64.321 | S11: 69.428 | T11: 66.965 | U11: 9.059 | V11: 14.852 | W11: 12.058 | X11: 22.181 | Y11: 3.14 | Z11: 12.323 | AA11: 69.173 | AB11: 65.064 | AC11: 67.046 | AD11: 411.479 | AE11: 407.573 | AF11: 409.572 | AG11: 11.091 | AH11: 9.5946299 | AI11: 2.554679 | AJ11: 6.0249711 | AK11: 6.788 | AL11: 1.848 | AM11: 4.231 | AN11: 85.212 | AO11: 67.58 | AP11: 76.13 | AQ11: 2.39 | AR11: 1.447 | AS11: 1.902 | AT11: 16.708 | AU11: 1.648 | AV11: 8.911 | AW11: 581.042 | AX11: 499.892 | AY11: 539.191 | AZ11: 5.81 | BA11: 4.999 | BB11: 5.392 | BC11: 39.645 | BD11: 8.96 | BE11: 15.944 | BF11: 18.814 | BG11: 100.544 | BH11: 14.642047
A12: 1998 | B12: Durango | C12: 15.746 | D12: 3.769 | E12: 9.706 | F12: 14.831 | G12: 10.196 | H12: 2.738 | I12: 1.481 | J12: 2.104 | K12: 12.597 | L12: 4.576 | M12: 8.552 | N12: 62.227 | O12: 102.417 | P12: 18.574 | Q12: 60.204 | R12: 42.582 | S12: 53.165 | T12: 47.919 | U12: 6.709 | V12: 9.556 | W12: 8.145 | X12: 32.45 | Y12: 3.096 | Z12: 17.647 | AA12: 48.333 | AB12: 33.245 | AC12: 40.724 | AD12: 332.717 | AE12: 271.477 | AF12: 301.903 | AG12: 10.817 | AH12: 6.9644188 | AI12: 1.7120297 | AJ12: 4.316112 | AK12: 6.025 | AL12: 0.808 | AM12: 3.394 | AN12: 48.059 | AO12: 32.303 | AP12: 40.113 | AQ12: 5.751 | AR12: 1.75 | AS12: 3.733 | AT12: 3.149 | AU12: 0 | AV12: 1.561 | AW12: 495.378 | AX12: 334.468 | AY12: 414.437 | AZ12: 4.954 | BA12: 3.345 | BB12: 4.144 | BC12: 61.455 | BD12: 28.644 | BE12: 22.683 | BF12: 26.672 | BG12: 45.854 | BH12: 2.1143803
A13: 1998 | B13: Guanajuato | C13: 22.922 | D13: 5.258 | E13: 13.831 | F13: 17.091 | G13: 13.633 | H13: 2.036 | I13: 1.419 | J13: 1.718 | K13: 7.7 | L13: 3.797 | M13: 5.691 | N13: 45.633 | O13: 81.468 | P13: 21.115 | Q13: 50.406 | R13: 46.907 | S13: 55.207 | T13: 51.179 | U13: 7.744 | V13: 11.934 | W13: 9.901 | X13: 12.523 | Y13: 1.377 | Z13: 6.787 | AA13: 39.827 | AB13: 33.341 | AC13: 36.489 | AD13: 340.075 | AE13: 302.16 | AF13: 320.647 | AG13: 7.257 | AH13: 10.647855 | AI13: 2.3523708 | AJ13: 6.332054 | AK13: 5.841 | AL13: 1.21 | AM13: 3.458 | AN13: 96.248 | AO13: 86.504 | AP13: 91.255 | AQ13: 2.611 | AR13: 1.627 | AS13: 2.105 | AT13: 3.54 | AU13: 0.376 | AV13: 1.911 | AW13: 521.906 | AX13: 415.621 | AY13: 467.312 | AZ13: 5.219 | BA13: 4.156 | BB13: 4.673 | BC13: 65.357 | BD13: 39.727 | BE13: 25.456 | BF13: 29.812 | BG13: 62.543 | BH13: 13.751834
... A492: 2012 | B492: Tamaulipas | C492: 17.99 | D492: 5.237 | E492: 11.637 | F492: 11.178 | G492: 18.95 | H492: 5.7 | I492: 4.131 | J492: 4.908 | K492: 11.103 | L492: 4.015 | M492: 7.523 | N492: 43.584 | O492: 146.589 | P492: 27.814 | Q492: 87.809 | R492: 70.474 | S492: 75.006 | T492: 72.763 | U492: 13.181 | V492: 15.129 | W492: 14.165 | X492: 78.489 | Y492: 9.834 | Z492: 44.669 | AA492: 94.282 | AB492: 64.706 | AC492: 79.345 | AD492: 414.83 | AE492: 350.182 | AF492: 382.239 | AG492: 10.034 | AH492: 6.9772687 | AI492: 1.4918916 | AJ492: 4.2638748 | AK492: 8.193 | AL492: 1.571 | AM492: 4.937 | AN492: 55.394 | AO492: 38.696 | AP492: 46.961 | AQ492: 4.572 | AR492: 1.455 | AS492: 2.997 | AT492: 8.787 | AU492: 2.211 | AV492: 5.466 | AW492: 625.362 | AX492: 423.558 | AY492: 524.738 | AZ492: 6.254 | BA492: 4.236 | BB492: 5.247 | BC492: 3.478 | BD492: 2.213 | BE492: 12.252 | BF492: 14.41 | BG492: 25.965 | BH492: 8.9578397
A493: 2012 | B493: Tlaxcala | C493: 13.916 | D493: 3.905 | E493: 8.844 | F493: 10.864 | G493: 12.675 | H493: 2.816 | I493: 3.905 | J493: 3.377 | K493: 2.816 | L493: 1.718 | M493: 2.251 | N493: 41.756 | O493: 71.238 | P493: 20.15 | Q493: 45.184 | R493: 90.125 | S493: 80.599 | T493: 85.222 | U493: 12.591 | V493: 16.87 | W493: 14.793 | X493: 9.609 | Y493: 2.343 | Z493: 6.03 | AA493: 39.761 | AB493: 29.99 | AC493: 34.732 | AD493: 377.067 | AE493: 328.801 | AF493: 352.224 | AG493: 8.615 | AH493: 8.9704488 | AI493: 1.6805381 | AJ493: 5.2952527 | AK493: 6.295 | AL493: 0.937 | AM493: 3.538 | AN493: 52.683 | AO493: 39.05 | AP493: 45.666 | AQ493: NA | AR493: NA | AS493: NA | AT493: 3.148 | AU493: 0.312 | AV493: 1.688 | AW493: 514.076 | AX493: 398.779 | AY493: 454.972 | AZ493: 5.141 | BA493: 3.988 | BB493: 4.55 | BC493: 20.332 | BD493: 3.91 | BE493: 14.934 | BF493: 17.2 | BG493: 59.44 | BH493: 9.0645665
A494: 2012 | B494: Veracruz | C494: 8.292 | D494: 2.277 | E494: 5.193 | F494: 15.979 | G494: 16.86 | H494: 4.378 | I494: 4.046 | J494: 4.207 | K494: 5.897 | L494: 3.198 | M494: 4.506 | N494: 49.107 | O494: 94.792 | P494: 19.89 | Q494: 56.509 | R494: 84.929 | S494: 92.616 | T494: 88.89 | U494: 21.091 | V494: 22.458 | W494: 21.795 | X494: 22.558 | Y494: 3.367 | Z494: 12.832 | AA494: 77.976 | AB494: 63.424 | AC494: 70.478 | AD494: 495.023 | AE494: 426.863 | AF494: 459.94 | AG494: 12.232 | AH494: 5.510349 | AI494: 2.0602698 | AJ494: 3.7719056 | AK494: 6.129 | AL494: 1.236 | AM494: 3.608 | AN494: 77.126 | AO494: 53.346 | AP494: 64.885 | AQ494: 5.202 | AR494: 1.768 | AS494: 3.433 | AT494: 13.829 | AU494: 3.973 | AV494: 8.75 | AW494: 679.61 | AX494: 512.599 | AY494: 593.992 | AZ494: 6.796 | BA494: 5.126 | BB494: 5.94 | BC494: 15.058 | BD494: 5.612 | BE494: 14.592 | BF494: 17.094 | BG494: 53.303 | BH494: 10.097944
A495: 2012 | B495: Yucatán | C495: 16.443 | D495: 2.207 | E495: 9.232 | F495: 14.844 | G495: 12.547 | H495: 2.56 | I495: 3.933 | J495: 3.256 | K495: 6.892 | L495: 2.398 | M495: 4.616 | N495: 34.426 | O495: 61.143 | P495: 14.007 | Q495: 37.269 | R495: 49.624 | S495: 67.54 | T495: 58.698 | U495: 9.058 | V495: 8.442 | W495: 8.746 | X495: 3.348 | Y495: 0.767 | Z495: 2.041 | AA495: 100.232 | AB495: 72.336 | AC495: 86.103 | AD495: 445.53 | AE495: 382.021 | AF495: 413.363 | AG495: 8.074 | AH495: 13.895894 | AI495: 4.1814214 | AJ495: 9.0761868 | AK495: 12.898 | AL495: 2.782 | AM495: 7.775 | AN495: 72.959 | AO495: 54.204 | AP495: 63.46 | AQ495: 1.477 | AR495: 1.151 | AS495: 1.312 | AT495: 10.535 | AU495: 2.494 | AV495: 6.463 | AW495: 597.453 | AX495: 468.748 | AY495: 532.265 | AZ495: 5.975 | BA495: 4.687 | BB495: 5.323 | BC495: 15.198 | BD495: 10.855 | BE495: 12.878 | BF495: 15.161 | BG495: 56.36 | BH495: 8.2567773
A496: 2012 | B496: Zacatecas | C496: 15.268 | D496: 3.759 | E496: 9.396 | F496: 7.098 | G496: 18.357 | H496: 4.828 | I496: 4.385 | J496: 4.602 | K496: 7.569 | L496: 5.764 | M496: 6.648 | N496: 59.306 | O496: 128.408 | P496: 34.205 | Q496: 80.732 | R496: 60.289 | S496: 58.638 | T496: 59.447 | U496: 17.747 | V496: 20.799 | W496: 19.304 | X496: 47.631 | Y496: 6.39 | Z496: 26.783 | AA496: 64.334 | AB496: 48.99 | AC496: 56.506 | AD496: 416.804 | AE496: 366.987 | AF496: 391.389 | AG496: 13.441 | AH496: 7.0013793 | AI496: 1.371728 | AJ496: 4.1575648 | AK496: 5.742 | AL496: 1.128 | AM496: 3.388 | AN496: 59.376 | AO496: 52.999 | AP496: 56.123 | AQ496: 2.088 | AR496: 1.128 | AS496: 1.598 | AT496: 1.174 | AU496: 0.251 | AV496: 0.703 | AW496: 615.81 | AX496: 462.211 | AY496: 537.832 | AZ496: 6.158 | BA496: 4.622 | BB496: 5.378 | BC496: 18.508 | BD496: 4.776 | BE496: 17.121 | BF496: 19.53 | BG496: 29.368 | BH496: 5.9910135
A497: 2013 | B497: Nacional | C497: 15.827 | D497: 3.867 | E497: 9.725 | F497: 11.764 | G497: 16.811 | H497: 4.676 | I497: 4.009 | J497: 4.335 | K497: 7.28 | L497: 4.029 | M497: 5.621 | N497: 45.211 | O497: 95.925 | P497: 20.895 | Q497: 57.809 | R497: 74.076 | S497: 75.408 | T497: 74.758 | U497: 14.863 | V497: 18.295 | W497: 16.616 | X497: 34.526 | Y497: 4.32 | Z497: 19.212 | AA497: 75.768 | AB497: 57.341 | AC497: 66.366 | AD497: 426.787 | AE497: 372.125 | AF497: 398.924 | AG497: 10.288 | AH497: 9.0031839 | AI497: 2.6862216 | AJ497: 5.8440607 | AK497: 8.223 | AL497: 1.76 | AM497: 4.924 | AN497: 61.314 | AO497: 48.171 | AP497: 54.646 | AQ497: 3.044 | AR497: 1.246 | AS497: 2.125 | AT497: 7.007 | AU497: 1.432 | AV497: 4.16 | AW497: 593.362 | AX497: 450.049 | AY497: 520.491 | AZ497: 5.934 | BA497: 4.5 | BB497: 5.205 | BC497: 21.02 | BD497: 9.397 | BE497: 14.062 | BF497: 16.516 | BG497: 38.084 | BH497: 7.4062901
A498: 2013 | B498: Aguascalientes | C498: 17.203 | D498: 7.579 | E498: 12.294 | F498: 7.756 | G498: 16.408 | H498: 3.788 | I498: 4.547 | J498: 4.175 | K498: 6.944 | L498: 4.396 | M498: 5.644 | N498: 49.638 | O498: 63.604 | P498: 25.465 | Q498: 44.227 | R498: 63.289 | S498: 57.296 | T498: 60.232 | U498: 16.098 | V498: 22.433 | W498: 19.33 | X498: 5.682 | Y498: 1.516 | Z498: 3.557 | AA498: 54.766 | AB498: 37.894 | AC498: 46.16 | AD498: 360.793 | AE498: 320.587 | AF498: 340.284 | AG498: 9.943 | AH498: 13.994178 | AI498: 4.0306978 | AJ498: 9.0325171 | AK498: 14.204 | AL498: 3.486 | AM498: 8.737 | AN498: 41.824 | AO498: 36.985 | AP498: 39.588 | AQ498: 1.105 | AR498: 1.364 | AS498: 1.237 | AT498: 4.577 | AU498: 0.758 | AV498: 2.629 | AW498: 468.905 | AX498: 386.068 | AY498: 426.959 | AZ498: 4.689 | BA498: 3.861 | BB498: 4.27 | BC498: 10.481 | BD498: 4.492 | BE498: 9.412 | BF498: 10.919 | BG498: 25.735 | BH498: 5.8088235
A499: 2013 | B499: Baja California | C499: 8.155 | D499: 2.668 | E499: 5.427 | F499: 12.342 | G499: 20.155 | H499: 6.356 | I499: 4.427 | J499: 5.397 | K499: 10.193 | L499: 5.336 | M499: 7.778 | N499: 42.468 | O499: 106.431 | P499: 24.316 | Q499: 65.996 | R499: 58.282 | S499: 55.424 | T499: 56.861 | U499: 12.052 | V499: 13.947 | W499: 12.994 | X499: 39.994 | Y499: 4.73 | Z499: 22.672 | AA499: 75.551 | AB499: 43.539 | AC499: 59.635 | AD499: 394.604 | AE499: 306.106 | AF499: 350.634 | AG499: 9.054 | AH499: 4.8904307 | AI499: 1.4728577 | AJ499: 3.2129856 | AK499: 6.056 | AL499: 1.334 | AM499: 3.708 | AN499: 75.851 | AO499: 45.54 | AP499: 60.811 | AQ499: 13.851 | AR499: 3.578 | AS499: 8.743 | AT499: 13.131 | AU499: 3.396 | AV499: 8.291 | AW499: 580.304 | AX499: 378.873 | AY499: 480.788 | AZ499: 5.803 | BA499: 3.789 | BB499: 4.808 | BC499: 12.193 | BD499: 3.726 | BE499: 11.818 | BF499: 13.899 | BG499: 42.333 | BH499: 6.7732035
A500: 2013 | B500: Baja California Sur | C500: 10.389 | D500: 2.631 | E500: 6.588 | F500: 8.163 | G500: 18.502 | H500: 6.177 | I500: 3.508 | J500: 4.87 | K500: 9.827 | L500: 6.139 | M500: 8.021 | N500: 41.736 | O500: 72.722 | P500: 20.464 | Q500: 47.121 | R500: 45.767 | S500: 47.653 | T500: 46.691 | U500: 10.108 | V500: 13.156 | W500: 11.601 | X500: 10.389 | Y500: 3.508 | Z500: 7.018 | AA500: 71.037 | AB500: 45.606 | AC500: 58.578 | AD500: 330.479 | AE500: 275.391 | AF500: 303.491 | AG500: 8.704 | AH500: 11.979904 | AI500: 3.2110976 | AJ500: 7.748184 | AK500: 11.231 | AL500: 2.923 | AM500: 7.161 | AN500: 51.664 | AO500: 29.235 | AP500: 40.675 | AQ500: 2.527 | AR500: 1.462 | AS500: 2.005 | AT500: 9.547 | AU500: 1.754 | AV500: 5.729 | AW500: 459.919 | AX500: 327.137 | AY500: 394.867 | AZ500: 4.599 | BA500: 3.271 | BB500: 3.949 | BC500: 13.887 | BD500: 7.715 | BE500: 11.158 | BF500: 13.246 | BG500: 32.11 | BH500: 7.2248535
A501: 2013 | B501: Campeche | C501: 13.859 | D501: 1.782 | E501: 7.76 | F501: 12.631 | G501: 10.526 | H501: 2.272 | I501: 3.786 | J501: 3.037 | K501: 3.181 | L501: 3.341 | M501: 3.262 | N501: 34.934 | O501: 73.155 | P501: 18.709 | Q501: 45.887 | R501: 61.341 | S501: 66.596 | T501: 63.995 | U501: 12.723 | V501: 10.914 | W501: 11.809 | X501: 13.404 | Y501: 3.118 | Z501: 8.21 | AA501: 79.516 | AB501: 49.669 | AC501: 64.445 | AD501: 389.629 | AE501: 311.377 | AF501: 350.453 | AG501: 7.952 | AH501: 14.385298 | AI501: 6.5454762 | AJ501: 10.451131 | AK501: 12.95 | AL501: 4.455 | AM501: 8.66 | AN501: 57.479 | AO501: 47.664 | AP501: 52.86 | AQ501: 3.408 | AR501: 0.891 | AS501: 2.137 | AT501: 11.132 | AU501: 3.118 | AV501: 7.086 | AW501: 538.211 | AX501: 392.45 | AY501: 465.508 | AZ501: 5.382 | BA501: 3.925 | BB501: 4.655 | BC501: 15.201 | BD501: 5.846 | BE501: 14.685 | BF501: 16.825 | BG501: 65.398 | BH501: 9.8692033
A502: 2013 | B502: Coahuila | C502: 14.144 | D502: 4.272 | E502: 9.19 | F502: 10.409 | G502: 24.626 | H502: 4.578 | I502: 5.086 | J502: 4.833 | K502: 11.274 | L502: 4.747 | M502: 7.998 | N502: 38.801 | O502: 107.823 | P502: 23.465 | Q502: 65.485 | R502: 74.889 | S502: 84.907 | T502: 79.916 | U502: 18.449 | V502: 19.192 | W502: 18.822 | X502: 47.079 | Y502: 7.121 | Z502: 27.025 | AA502: 89.443 | AB502: 61.645 | AC502: 75.492 | AD502: 430.268 | AE502: 386.963 | AF502: 408.67 | AG502: 8.814 | AH502: 10.689018 | AI502: 1.90588 | AJ502: 6.3711872 | AK502: 10.454 | AL502: 1.424 | AM502: 5.922 | AN502: 55.62 | AO502: 45.098 | AP502: 50.475 | AQ502: 4.168 | AR502: 1.628 | AS502: 2.893 | AT502: 5.671 | AU502: 1.695 | AV502: 3.676 | AW502: 603.961 | AX502: 465.834 | AY502: 534.91 | AZ502: 6.04 | BA502: 4.658 | BB502: 5.349 | BC502: 10.914 | BD502: 3.873 | BE502: 11.917 | BF502: 13.571 | BG502: 27.006 | BH502: 8.236982
A503: 2013 | B503: Colima | C503: 19.186 | D503: 4.805 | E503: 11.949 | F503: 8.767 | G503: 21.661 | H503: 5.154 | I503: 3.392 | J503: 4.267 | K503: 8.877 | L503: 4.805 | M503: 6.828 | N503: 69.208 | O503: 120.84 | P503: 25.723 | Q503: 72.974 | R503: 84.76 | S503: 76.603 | T503: 80.655 | U503: 13.172 | V503: 14.416 | W503: 13.798 | X503: 56.125 | Y503: 4.523 | Z503: 30.157 | AA503: 83.901 | AB503: 60.774 | AC503: 72.405 | AD503: 452.722 | AE503: 360.968 | AF503: 406.69 | AG503: 16.036 | AH503: 11.514282 | AI503: 2.3326154 | AJ503: 6.952921 | AK503: 12.886 | AL503: 1.979 | AM503: 7.397 | AN503: 62.711 | AO503: 37.595 | AP503: 50.072 | AQ503: 4.295 | AR503: 1.979 | AS503: 3.129 | AT503: 11.454 | AU503: 3.675 | AV503: 7.539 | AW503: 643.718 | AX503: 435.593 | AY503: 539.124 | AZ503: 6.437 | BA503: 4.356 | BB503: 5.391 | BC503: 3.144 | BD503: 6.288 | BE503: 14.157 | BF503: 16.516 | BG503: 24.408 | BH503: 5.2884224
A504: 2013 | B504: Chiapas | C504: 12.609 | D504: 1.881 | E504: 7.145 | F504: 17.552 | G504: 12.082 | H504: 3.084 | I504: 2.332 | J504: 2.701 | K504: 4.099 | L504: 3.084 | M504: 3.582 | N504: 54.451 | O504: 69.135 | P504: 15.157 | Q504: 41.663 | R504: 44.346 | S504: 54.535 | T504: 49.536 | U504: 10.501 | V504: 12.675 | W504: 11.608 | X504: 15.459 | Y504: 3.046 | Z504: 9.156 | AA504: 46.689 | AB504: 35.128 | AC504: 40.801 | AD504: 323.581 | AE504: 285.349 | AF504: 304.147 | AG504: 10.15 | AH504: 11.390074 | AI504: 2.8868694 | AJ504: 7.0771788 | AK504: 10.189 | AL504: 2.031 | AM504: 6.034 | AN504: 67.574 | AO504: 57.807 | AP504: 62.619 | AQ504: 3.709 | AR504: 1.993 | AS504: 2.835 | AT504: 7.144 | AU504: 2.332 | AV504: 4.693 | AW504: 496.672 | AX504: 390.921 | AY504: 442.889 | AZ504: 4.967 | BA504: 3.909 | BB504: 4.429 | BC504: 40.333 | BD504: 32.512 | BE504: 17.256 | BF504: 20.796 | BG504: 45.161 | BH504: 5.5358079
A505: 2013 | B505: Chihuahua | C505: 19.154 | D505: 6.083 | E505: 12.578 | F505: 12.881 | G505: 21.154 | H505: 7.119 | I505: 5.357 | J505: 6.233 | K505: 11.865 | L505: 6.641 | M505: 9.265 | N505: 49.751 | O505: 196.793 | P505: 37.389 | Q505: 116.989 | R505: 62.094 | S505: 70.871 | T505: 66.538 | U505: 16.272 | V505: 20.09 | W505: 18.193 | X505: 109.16 | Y505: 10.324 | Z505: 59.688 | AA505: 103.566 | AB505: 72.601 | AC505: 88.128 | AD505: 470.652 | AE505: 405.976 | AF505: 438.422 | AG505: 11.244 | AH505: 15.707217 | AI505: 4.6382476 | AJ505: 10.23751 | AK505: 14.182 | AL505: 3.237 | AM505: 8.703 | AN505: 71.022 | AO505: 55.19 | AP505: 63.169 | AQ505: 4.238 | AR505: 1.674 | AS505: 2.948 | AT505: 6.159 | AU505: 1.228 | AV505: 3.678 | AW505: 746.885 | AX505: 505.81 | AY505: 626.47 | AZ505: 7.469 | BA505: 5.058 | BB505: 6.265 | BC505: 25.686 | BD505: 11.008 | BE505: 16.615 | BF505: 19.802 | BG505: 66.33 | BH505: 9.8362777
... A859: 2023 | B859: Zacatecas | C859: 13.248 | D859: 2.79 | E859: 7.902 | F859: 7.243 | G859: 19.866 | H859: 4.862 | I859: 4.766 | J859: 4.813 | K859: 7.657 | L859: 4.65 | M859: 6.12 | N859: 55.032 | O859: 163.475 | P859: 33.711 | Q859: 97.207 | R859: 67.213 | S859: 73.118 | T859: 70.231 | U859: 14.707 | V859: 21.156 | W859: 18.003 | X859: 91.4 | Y859: 12.089 | Z859: 50.921 | AA859: 112.792 | AB859: 81.952 | AC859: 97.028 | AD859: 505.497 | AE859: 439.636 | AF859: 471.951 | AG859: 14.585 | AH859: 12.397505 | AI859: 5.1536474 | AJ859: 8.7713716 | AK859: 10.696 | AL859: 2.557 | AM859: 6.536 | AN859: 61.622 | AO859: 52.426 | AP859: 56.922 | AQ859: 1.823 | AR859: 0.814 | AS859: 1.307 | AT859: 1.459 | AU859: 0.581 | AV859: 1.01 | AW859: 738.616 | AX859: 530.074 | AY859: 632.2 | AZ859: 7.386 | BA859: 5.301 | BB859: 6.322 | BC859: 14.835 | BD859: 5.16 | BE859: 13.551 | BF859: 15.465 | BG859: 19.131 | BH859: 7.9714304

Sheet NACIONAL
A1: Año | B1: Tasa de mortalidad por accidentes de tráfico de vehículo de motor en hombres | C1: Tasa de mortalidad por accidentes de tráfico de vehículo de motor en mujeres | D1: Tasa de mortalidad por accidentes de tráfico de vehículo de motor | E1: Tasa de mortalidad por tumor maligno del cuello del útero en mujeres mayores de 25 años | F1: Tasa de mortalidad por tumor maligno de la mama en mujeres mayores de 25 años | G1: Tasa de mortalidad por tumor maligno del colon y recto en hombres | H1: Tasa de mortalidad por tumor maligno del colon y recto en mujeres | I1: Tasa de mortalidad por tumor maligno del colon y recto | J1: Tasa de mortalidad por tumor maligno de tráquea, bronquios y pulmón en hombres | K1: Tasa de mortalidad por tumor maligno de tráquea, bronquios y pulmón en mujeres | L1: Tasa de mortalidad por tumor maligno de tráquea, bronquios y pulmón | M1: Tasa de mortalidad por tumor maligno de la próstata en hombres mayores de 45 años | N1: Tasa de mortalidad por causas externas de morbilidad y mortalidad en hombres | O1: Tasa de mortalidad por causas externas de morbilidad y mortalidad en mujeres | P1: Tasa de mortalidad por causas externas de morbilidad y mortalidad | Q1: Tasa de mortalidad por diabetes mellitus en hombres | R1: Tasa de mortalidad por diabetes mellitus en mujeres | S1: Tasa de mortalidad por diabetes mellitus | T1: Tasa de mortalidad por enfermedades hipertensivas en hombres | U1: Tasa de mortalidad por enfermedades hipertensivas en mujeres | V1: Tasa de mortalidad por enfermedades hipertensivas | W1: Tasa de mortalidad por agresiones (homicidios) en hombres | X1: Tasa de mortalidad por agresiones (homicidios) en mujeres | Y1: Tasa de mortalidad por agresiones (homicidios) | Z1: Tasa de mortalidad por enfermedades isquémicas del corazón en hombres | AA1: Tasa de mortalidad por enfermedades isquémicas del corazón en mujeres | AB1: Tasa de mortalidad por enfermedades isquémicas del corazón | AC1: Tasa de mortalidad por enfermedades no transmisibles en hombres | AD1: Tasa de mortalidad por enfermedades no transmisibles en mujeres | AE1: Tasa de mortalidad por enfermedades no transmisibles | AF1: Tasa de mortalidad por tumor maligno de la próstata | AG1: Tasa de mortalidad por lesiones autoinfligidas intencionalmente (suicidios) en hombres de 10 a 29 años | AH1: Tasa de mortalidad por lesiones autoinfligidas intencionalmente (suicidios) en mujeres de 10 a 29 años | AI1: Tasa de mortalidad por lesiones autoinfligidas intencionalmente (suicidios) de 10 a 29 años | AJ1: Tasa de mortalidad por lesiones autoinfligidas intencionalmente (suicidios) en hombres | AK1: Tasa de mortalidad por lesiones autoinfligidas intencionalmente (suicidios) en mujeres | AL1: Tasa de mortalidad por lesiones autoinfligidas intencionalmente (suicidios) | AM1: Tasa de mortalidad por enfermedades transmisibles, maternas, perinatales y nutricionales en hombres | AN1: Tasa de mortalidad por enfermedades transmisibles, maternas, perinatales y nutricionales en mujeres | AO1: Tasa de mortalidad por enfermedades transmisibles, maternas, perinatales y nutricionales | AP1: Tasa de mortalidad por tuberculosis en hombres | AQ1: Tasa de mortalidad por tuberculosis en mujeres | AR1: Tasa de mortalidad por tuberculosis | AS1: Tasa de mortalidad por VIH/SIDA en hombres | AT1: Tasa de mortalidad por VIH/SIDA en mujeres | AU1: Tasa de mortalidad por VIH/SIDA | AV1: Tasa de mortalidad por cada 100,000 habitantes en hombres | AW1: Tasa de mortalidad por cada 100,000 habitantes en mujeres | AX1: Tasa de mortalidad por cada 100,000 habitantes | AY1: Tasa de mortalidad por cada 1000 habitantes en hombres | AZ1: Tasa de mortalidad por cada 1000 habitantes en mujeres | BA1: Tasa de mortalidad por cada 1000 habitantes | BB1: Tasa de mortalidad en niños menores de 5 años por enfermedades respiratorias agudas (defunciones por cada 100 mil menores de 5 años) | BC1: Tasa de mortalidad en niños menores de 5 años por enfermedades diarreicas (defunciones por cada 100 mil menores de 5 años) | BD1: Tasa de mortalidad infantil | BE1: Tasa de mortalidad infantil (menores de 5 años) | BF1: Razón de mortalidad materna (defunciones por cada 100 mil nacidos vivos) | BG1: Tasa de mortalidad Neonatal
A2: 1998 | B2: =SUMIFS(Concentrado!C$2:C826,Concentrado!$A$2:$A826,"="&$A2,Concentrado!$B$2:$B826, "=Nacional") -> 17.305 | C2: =SUMIFS(Concentrado!D$2:D826,Concentrado!$A$2:$A826,"="&$A2,Concentrado!$B$2:$B826, "=Nacional") -> 4.525 | D2: =SUMIFS(Concentrado!E$2:E826,Concentrado!$A$2:$A826,"="&$A2,Concentrado!$B$2:$B826, "=Nacional") -> 10.837 | E2: =SUMIFS(Concentrado!F$2:F826,Concentrado!$A$2:$A826,"="&$A2,Concentrado!$B$2:$B826, "=Nacional") -> 20.354 | F2: =SUMIFS(Concentrado!G$2:G826,Concentrado!$A$2:$A826,"="&$A2,Concentrado!$B$2:$B826, "=Nacional") -> 15.094 | G2: =SUMIFS(Concentrado!H$2:H826,Concentrado!$A$2:$A826,"="&$A2,Concentrado!$B$2:$B826, "=Nacional") -> 2.43 | H2: =SUMIFS(Concentrado!I$2:I826,Concentrado!$A$2:$A826,"="&$A2,Concentrado!$B$2:$B826, "=Nacional") -> 2.44 | I2: =SUMIFS(Concentrado!J$2:J826,Concentrado!$A$2:$A826,"="&$A2,Concentrado!$B$2:$B826, "=Nacional") -> 2.435 | ... BG2: =SUMIFS(Concentrado!BH$2:BH826,Concentrado!$A$2:$A826,"="&$A2,Concentrado!$B$2:$B826, "=Nacional") -> 10.381644
A3: 1999 | B3: =SUMIFS(Concentrado!C$2:C859,Concentrado!$A$2:$A859,"="&$A3,Concentrado!$B$2:$B859, "=Nacional") -> 16.952 | C3: =SUMIFS(Concentrado!D$2:D859,Concentrado!$A$2:$A859,"="&$A3,Concentrado!$B$2:$B859, "=Nacional") -> 4.488 | D3: =SUMIFS(Concentrado!E$2:E859,Concentrado!$A$2:$A859,"="&$A3,Concentrado!$B$2:$B859, "=Nacional") -> 10.636 | E3: =SUMIFS(Concentrado!F$2:F859,Concentrado!$A$2:$A859,"="&$A3,Concentrado!$B$2:$B859, "=Nacional") -> 19.946 | F3: =SUMIFS(Concentrado!G$2:G859,Concentrado!$A$2:$A859,"="&$A3,Concentrado!$B$2:$B859, "=Nacional") -> 14.819 | G3: =SUMIFS(Concentrado!H$2:H859,Concentrado!$A$2:$A859,"="&$A3,Concentrado!$B$2:$B859, "=Nacional") -> 2.473 | H3: =SUMIFS(Concentrado!I$2:I859,Concentrado!$A$2:$A859,"="&$A3,Concentrado!$B$2:$B859, "=Nacional") -> 2.56 | I3: =SUMIFS(Concentrado!J$2:J859,Concentrado!$A$2:$A859,"="&$A3,Concentrado!$B$2:$B859, "=Nacional") -> 2.517 | ... BG3: =SUMIFS(Concentrado!BH$2:BH859,Concentrado!$A$2:$A859,"="&$A3,Concentrado!$B$2:$B859, "=Nacional") -> 9.6637209
A4: 2000 | B4: =SUMIFS(Concentrado!C$2:C859,Concentrado!$A$2:$A859,"="&$A4,Concentrado!$B$2:$B859, "=Nacional") -> 16.766 | C4: =SUMIFS(Concentrado!D$2:D859,Concentrado!$A$2:$A859,"="&$A4,Concentrado!$B$2:$B859, "=Nacional") -> 4.457 | D4: =SUMIFS(Concentrado!E$2:E859,Concentrado!$A$2:$A859,"="&$A4,Concentrado!$B$2:$B859, "=Nacional") -> 10.52 | E4: =SUMIFS(Concentrado!F$2:F859,Concentrado!$A$2:$A859,"="&$A4,Concentrado!$B$2:$B859, "=Nacional") -> 19.533 | F4: =SUMIFS(Concentrado!G$2:G859,Concentrado!$A$2:$A859,"="&$A4,Concentrado!$B$2:$B859, "=Nacional") -> 14.566 | G4: =SUMIFS(Concentrado!H$2:H859,Concentrado!$A$2:$A859,"="&$A4,Concentrado!$B$2:$B859, "=Nacional") -> 2.655 | H4: =SUMIFS(Concentrado!I$2:I859,Concentrado!$A$2:$A859,"="&$A4,Concentrado!$B$2:$B859, "=Nacional") -> 2.578 | I4: =SUMIFS(Concentrado!J$2:J859,Concentrado!$A$2:$A859,"="&$A4,Concentrado!$B$2:$B859, "=Nacional") -> 2.616 | ... BG4: =SUMIFS(Concentrado!BH$2:BH859,Concentrado!$A$2:$A859,"="&$A4,Concentrado!$B$2:$B859, "=Nacional") -> 9.5728911
A5: 2001 | B5: =SUMIFS(Concentrado!C$2:C859,Concentrado!$A$2:$A859,"="&$A5,Concentrado!$B$2:$B859, "=Nacional") -> 16.617 | C5: =SUMIFS(Concentrado!D$2:D859,Concentrado!$A$2:$A859,"="&$A5,Concentrado!$B$2:$B859, "=Nacional") -> 4.632 | D5: =SUMIFS(Concentrado!E$2:E859,Concentrado!$A$2:$A859,"="&$A5,Concentrado!$B$2:$B859, "=Nacional") -> 10.538 | E5: =SUMIFS(Concentrado!F$2:F859,Concentrado!$A$2:$A859,"="&$A5,Concentrado!$B$2:$B859, "=Nacional") -> 18.547 | F5: =SUMIFS(Concentrado!G$2:G859,Concentrado!$A$2:$A859,"="&$A5,Concentrado!$B$2:$B859, "=Nacional") -> 14.767 | G5: =SUMIFS(Concentrado!H$2:H859,Concentrado!$A$2:$A859,"="&$A5,Concentrado!$B$2:$B859, "=Nacional") -> 2.681 | H5: =SUMIFS(Concentrado!I$2:I859,Concentrado!$A$2:$A859,"="&$A5,Concentrado!$B$2:$B859, "=Nacional") -> 2.719 | I5: =SUMIFS(Concentrado!J$2:J859,Concentrado!$A$2:$A859,"="&$A5,Concentrado!$B$2:$B859, "=Nacional") -> 2.7 | ... BG5: =SUMIFS(Concentrado!BH$2:BH859,Concentrado!$A$2:$A859,"="&$A5,Concentrado!$B$2:$B859, "=Nacional") -> 9.0808031
A6: 2002 | B6: =SUMIFS(Concentrado!C$2:C859,Concentrado!$A$2:$A859,"="&$A6,Concentrado!$B$2:$B859, "=Nacional") -> 16.639 | C6: =SUMIFS(Concentrado!D$2:D859,Concentrado!$A$2:$A859,"="&$A6,Concentrado!$B$2:$B859, "=Nacional") -> 4.623 | D6: =SUMIFS(Concentrado!E$2:E859,Concentrado!$A$2:$A859,"="&$A6,Concentrado!$B$2:$B859, "=Nacional") -> 10.545 | E6: =SUMIFS(Concentrado!F$2:F859,Concentrado!$A$2:$A859,"="&$A6,Concentrado!$B$2:$B859, "=Nacional") -> 17.317 | F6: =SUMIFS(Concentrado!G$2:G859,Concentrado!$A$2:$A859,"="&$A6,Concentrado!$B$2:$B859, "=Nacional") -> 15.421 | G6: =SUMIFS(Concentrado!H$2:H859,Concentrado!$A$2:$A859,"="&$A6,Concentrado!$B$2:$B859, "=Nacional") -> 2.666 | H6: =SUMIFS(Concentrado!I$2:I859,Concentrado!$A$2:$A859,"="&$A6,Concentrado!$B$2:$B859, "=Nacional") -> 2.651 | I6: =SUMIFS(Concentrado!J$2:J859,Concentrado!$A$2:$A859,"="&$A6,Concentrado!$B$2:$B859, "=Nacional") -> 2.658 | ... BG6: =SUMIFS(Concentrado!BH$2:BH859,Concentrado!$A$2:$A859,"="&$A6,Concentrado!$B$2:$B859, "=Nacional") -> 9.3959155
A7: 2003 | B7: =SUMIFS(Concentrado!C$2:C859,Concentrado!$A$2:$A859,"="&$A7,Concentrado!$B$2:$B859, "=Nacional") -> 16.834 | C7: =SUMIFS(Concentrado!D$2:D859,Concentrado!$A$2:$A859,"="&$A7,Concentrado!$B$2:$B859, "=Nacional") -> 4.798 | D7: =SUMIFS(Concentrado!E$2:E859,Concentrado!$A$2:$A859,"="&$A7,Concentrado!$B$2:$B859, "=Nacional") -> 10.73 | E7: =SUMIFS(Concentrado!F$2:F859,Concentrado!$A$2:$A859,"="&$A7,Concentrado!$B$2:$B859, "=Nacional") -> 16.931 | F7: =SUMIFS(Concentrado!G$2:G859,Concentrado!$A$2:$A859,"="&$A7,Concentrado!$B$2:$B859, "=Nacional") -> 15.175 | G7: =SUMIFS(Concentrado!H$2:H859,Concentrado!$A$2:$A859,"="&$A7,Concentrado!$B$2:$B859, "=Nacional") -> 2.808 | H7: =SUMIFS(Concentrado!I$2:I859,Concentrado!$A$2:$A859,"="&$A7,Concentrado!$B$2:$B859, "=Nacional") -> 2.884 | I7: =SUMIFS(Concentrado!J$2:J859,Concentrado!$A$2:$A859,"="&$A7,Concentrado!$B$2:$B859, "=Nacional") -> 2.848 | ... BG7: =SUMIFS(Concentrado!BH$2:BH859,Concentrado!$A$2:$A859,"="&$A7,Concentrado!$B$2:$B859, "=Nacional") -> 8.7733319
A8: 2004 | B8: =SUMIFS(Concentrado!C$2:C859,Concentrado!$A$2:$A859,"="&$A8,Concentrado!$B$2:$B859, "=Nacional") -> 16.99 | C8: =SUMIFS(Concentrado!D$2:D859,Concentrado!$A$2:$A859,"="&$A8,Concentrado!$B$2:$B859, "=Nacional") -> 4.73 | D8: =SUMIFS(Concentrado!E$2:E859,Concentrado!$A$2:$A859,"="&$A8,Concentrado!$B$2:$B859, "=Nacional") -> 10.758 | E8: =SUMIFS(Concentrado!F$2:F859,Concentrado!$A$2:$A859,"="&$A8,Concentrado!$B$2:$B859, "=Nacional") -> 16.19 | F8: =SUMIFS(Concentrado!G$2:G859,Concentrado!$A$2:$A859,"="&$A8,Concentrado!$B$2:$B859, "=Nacional") -> 15.895 | G8: =SUMIFS(Concentrado!H$2:H859,Concentrado!$A$2:$A859,"="&$A8,Concentrado!$B$2:$B859, "=Nacional") -> 2.997 | H8: =SUMIFS(Concentrado!I$2:I859,Concentrado!$A$2:$A859,"="&$A8,Concentrado!$B$2:$B859, "=Nacional") -> 2.997 | I8: =SUMIFS(Concentrado!J$2:J859,Concentrado!$A$2:$A859,"="&$A8,Concentrado!$B$2:$B859, "=Nacional") -> 2.997 | ... BG8: =SUMIFS(Concentrado!BH$2:BH859,Concentrado!$A$2:$A859,"="&$A8,Concentrado!$B$2:$B859, "=Nacional") -> 8.5904917
A9: 2005 | B9: =SUMIFS(Concentrado!C$2:C859,Concentrado!$A$2:$A859,"="&$A9,Concentrado!$B$2:$B859, "=Nacional") -> 17.869 | C9: =SUMIFS(Concentrado!D$2:D859,Concentrado!$A$2:$A859,"="&$A9,Concentrado!$B$2:$B859, "=Nacional") -> 4.786 | D9: =SUMIFS(Concentrado!E$2:E859,Concentrado!$A$2:$A859,"="&$A9,Concentrado!$B$2:$B859, "=Nacional") -> 11.206 | E9: =SUMIFS(Concentrado!F$2:F859,Concentrado!$A$2:$A859,"="&$A9,Concentrado!$B$2:$B859, "=Nacional") -> 15.852 | F9: =SUMIFS(Concentrado!G$2:G859,Concentrado!$A$2:$A859,"="&$A9,Concentrado!$B$2:$B859, "=Nacional") -> 15.695 | G9: =SUMIFS(Concentrado!H$2:H859,Concentrado!$A$2:$A859,"="&$A9,Concentrado!$B$2:$B859, "=Nacional") -> 3.25 | H9: =SUMIFS(Concentrado!I$2:I859,Concentrado!$A$2:$A859,"="&$A9,Concentrado!$B$2:$B859, "=Nacional") -> 3.064 | I9: =SUMIFS(Concentrado!J$2:J859,Concentrado!$A$2:$A859,"="&$A9,Concentrado!$B$2:$B859, "=Nacional") -> 3.155 | ... BG9: =SUMIFS(Concentrado!BH$2:BH859,Concentrado!$A$2:$A859,"="&$A9,Concentrado!$B$2:$B859, "=Nacional") -> 8.6162426
A10: 2006 | B10: =SUMIFS(Concentrado!C$2:C859,Concentrado!$A$2:$A859,"="&$A10,Concentrado!$B$2:$B859, "=Nacional") -> 18.372 | C10: =SUMIFS(Concentrado!D$2:D859,Concentrado!$A$2:$A859,"="&$A10,Concentrado!$B$2:$B859, "=Nacional") -> 4.795 | D10: =SUMIFS(Concentrado!E$2:E859,Concentrado!$A$2:$A859,"="&$A10,Concentrado!$B$2:$B859, "=Nacional") -> 11.443 | E10: =SUMIFS(Concentrado!F$2:F859,Concentrado!$A$2:$A859,"="&$A10,Concentrado!$B$2:$B859, "=Nacional") -> 14.954 | F10: =SUMIFS(Concentrado!G$2:G859,Concentrado!$A$2:$A859,"="&$A10,Concentrado!$B$2:$B859, "=Nacional") -> 16.139 | G10: =SUMIFS(Concentrado!H$2:H859,Concentrado!$A$2:$A859,"="&$A10,Concentrado!$B$2:$B859, "=Nacional") -> 3.272 | H10: =SUMIFS(Concentrado!I$2:I859,Concentrado!$A$2:$A859,"="&$A10,Concentrado!$B$2:$B859, "=Nacional") -> 3.061 | I10: =SUMIFS(Concentrado!J$2:J859,Concentrado!$A$2:$A859,"="&$A10,Concentrado!$B$2:$B859, "=Nacional") -> 3.164 | ... BG10: =SUMIFS(Concentrado!BH$2:BH859,Concentrado!$A$2:$A859,"="&$A10,Concentrado!$B$2:$B859, "=Nacional") -> 8.2226711
A11: 2007 | B11: =SUMIFS(Concentrado!C$2:C859,Concentrado!$A$2:$A859,"="&$A11,Concentrado!$B$2:$B859, "=Nacional") -> 16.394 | C11: =SUMIFS(Concentrado!D$2:D859,Concentrado!$A$2:$A859,"="&$A11,Concentrado!$B$2:$B859, "=Nacional") -> 4.337 | D11: =SUMIFS(Concentrado!E$2:E859,Concentrado!$A$2:$A859,"="&$A11,Concentrado!$B$2:$B859, "=Nacional") -> 10.232 | E11: =SUMIFS(Concentrado!F$2:F859,Concentrado!$A$2:$A859,"="&$A11,Concentrado!$B$2:$B859, "=Nacional") -> 14.213 | F11: =SUMIFS(Concentrado!G$2:G859,Concentrado!$A$2:$A859,"="&$A11,Concentrado!$B$2:$B859, "=Nacional") -> 16.204 | G11: =SUMIFS(Concentrado!H$2:H859,Concentrado!$A$2:$A859,"="&$A11,Concentrado!$B$2:$B859, "=Nacional") -> 3.376 | H11: =SUMIFS(Concentrado!I$2:I859,Concentrado!$A$2:$A859,"="&$A11,Concentrado!$B$2:$B859, "=Nacional") -> 3.368 | I11: =SUMIFS(Concentrado!J$2:J859,Concentrado!$A$2:$A859,"="&$A11,Concentrado!$B$2:$B859, "=Nacional") -> 3.371 | ... BG11: =SUMIFS(Concentrado!BH$2:BH859,Concentrado!$A$2:$A859,"="&$A11,Concentrado!$B$2:$B859, "=Nacional") -> 7.9983841
A12: 2008 | B12: =SUMIFS(Concentrado!C$2:C859,Concentrado!$A$2:$A859,"="&$A12,Concentrado!$B$2:$B859, "=Nacional") -> 18.533 | C12: =SUMIFS(Concentrado!D$2:D859,Concentrado!$A$2:$A859,"="&$A12,Concentrado!$B$2:$B859, "=Nacional") -> 4.818 | D12: =SUMIFS(Concentrado!E$2:E859,Concentrado!$A$2:$A859,"="&$A12,Concentrado!$B$2:$B859, "=Nacional") -> 11.52 | E12: =SUMIFS(Concentrado!F$2:F859,Concentrado!$A$2:$A859,"="&$A12,Concentrado!$B$2:$B859, "=Nacional") -> 13.837 | F12: =SUMIFS(Concentrado!G$2:G859,Concentrado!$A$2:$A859,"="&$A12,Concentrado!$B$2:$B859, "=Nacional") -> 16.537 | G12: =SUMIFS(Concentrado!H$2:H859,Concentrado!$A$2:$A859,"="&$A12,Concentrado!$B$2:$B859, "=Nacional") -> 3.805 | H12: =SUMIFS(Concentrado!I$2:I859,Concentrado!$A$2:$A859,"="&$A12,Concentrado!$B$2:$B859, "=Nacional") -> 3.43 | I12: =SUMIFS(Concentrado!J$2:J859,Concentrado!$A$2:$A859,"="&$A12,Concentrado!$B$2:$B859, "=Nacional") -> 3.614 | ... BG12: =SUMIFS(Concentrado!BH$2:BH859,Concentrado!$A$2:$A859,"="&$A12,Concentrado!$B$2:$B859, "=Nacional") -> 7.8976823
A13: 2009 | B13: =SUMIFS(Concentrado!C$2:C859,Concentrado!$A$2:$A859,"="&$A13,Concentrado!$B$2:$B859, "=Nacional") -> 18.184 | C13: =SUMIFS(Concentrado!D$2:D859,Concentrado!$A$2:$A859,"="&$A13,Concentrado!$B$2:$B859, "=Nacional") -> 4.805 | D13: =SUMIFS(Concentrado!E$2:E859,Concentrado!$A$2:$A859,"="&$A13,Concentrado!$B$2:$B859, "=Nacional") -> 11.345 | E13: =SUMIFS(Concentrado!F$2:F859,Concentrado!$A$2:$A859,"="&$A13,Concentrado!$B$2:$B859, "=Nacional") -> 13.72 | F13: =SUMIFS(Concentrado!G$2:G859,Concentrado!$A$2:$A859,"="&$A13,Concentrado!$B$2:$B859, "=Nacional") -> 16.422 | G13: =SUMIFS(Concentrado!H$2:H859,Concentrado!$A$2:$A859,"="&$A13,Concentrado!$B$2:$B859, "=Nacional") -> 3.662 | H13: =SUMIFS(Concentrado!I$2:I859,Concentrado!$A$2:$A859,"="&$A13,Concentrado!$B$2:$B859, "=Nacional") -> 3.058 | I13: =SUMIFS(Concentrado!J$2:J859,Concentrado!$A$2:$A859,"="&$A13,Concentrado!$B$2:$B859, "=Nacional") -> 3.353 | ... BG13: =SUMIFS(Concentrado!BH$2:BH859,Concentrado!$A$2:$A859,"="&$A13,Concentrado!$B$2:$B859, "=Nacional") -> 7.8305937
A14: 2010 | B14: =SUMIFS(Concentrado!C$2:C859,Concentrado!$A$2:$A859,"="&$A14,Concentrado!$B$2:$B859, "=Nacional") -> 16.619 | C14: =SUMIFS(Concentrado!D$2:D859,Concentrado!$A$2:$A859,"="&$A14,Concentrado!$B$2:$B859, "=Nacional") -> 4.457 | D14: =SUMIFS(Concentrado!E$2:E859,Concentrado!$A$2:$A859,"="&$A14,Concentrado!$B$2:$B859, "=Nacional") -> 10.411 | E14: =SUMIFS(Concentrado!F$2:F859,Concentrado!$A$2:$A859,"="&$A14,Concentrado!$B$2:$B859, "=Nacional") -> 12.907 | F14: =SUMIFS(Concentrado!G$2:G859,Concentrado!$A$2:$A859,"="&$A14,Concentrado!$B$2:$B859, "=Nacional") -> 16.474 | G14: =SUMIFS(Concentrado!H$2:H859,Concentrado!$A$2:$A859,"="&$A14,Concentrado!$B$2:$B859, "=Nacional") -> 3.799 | H14: =SUMIFS(Concentrado!I$2:I859,Concentrado!$A$2:$A859,"="&$A14,Concentrado!$B$2:$B859, "=Nacional") -> 3.264 | I14: =SUMIFS(Concentrado!J$2:J859,Concentrado!$A$2:$A859,"="&$A14,Concentrado!$B$2:$B859, "=Nacional") -> 3.527 | ... BG14: =SUMIFS(Concentrado!BH$2:BH859,Concentrado!$A$2:$A859,"="&$A14,Concentrado!$B$2:$B859, "=Nacional") -> 7.7002025
A15: 2011 | B15: =SUMIFS(Concentrado!C$2:C859,Concentrado!$A$2:$A859,"="&$A15,Concentrado!$B$2:$B859, "=Nacional") -> 16.916 | C15: =SUMIFS(Concentrado!D$2:D859,Concentrado!$A$2:$A859,"="&$A15,Concentrado!$B$2:$B859, "=Nacional") -> 4.292 | D15: =SUMIFS(Concentrado!E$2:E859,Concentrado!$A$2:$A859,"="&$A15,Concentrado!$B$2:$B859, "=Nacional") -> 10.481 | E15: =SUMIFS(Concentrado!F$2:F859,Concentrado!$A$2:$A859,"="&$A15,Concentrado!$B$2:$B859, "=Nacional") -> 12.475 | F15: =SUMIFS(Concentrado!G$2:G859,Concentrado!$A$2:$A859,"="&$A15,Concentrado!$B$2:$B859, "=Nacional") -> 16.619 | G15: =SUMIFS(Concentrado!H$2:H859,Concentrado!$A$2:$A859,"="&$A15,Concentrado!$B$2:$B859, "=Nacional") -> 3.929 | H15: =SUMIFS(Concentrado!I$2:I859,Concentrado!$A$2:$A859,"="&$A15,Concentrado!$B$2:$B859, "=Nacional") -> 3.416 | I15: =SUMIFS(Concentrado!J$2:J859,Concentrado!$A$2:$A859,"="&$A15,Concentrado!$B$2:$B859, "=Nacional") -> 3.668 | ... BG15: =SUMIFS(Concentrado!BH$2:BH859,Concentrado!$A$2:$A859,"="&$A15,Concentrado!$B$2:$B859, "=Nacional") -> 8.0254567
A16: 2012 | B16: =SUMIFS(Concentrado!C$2:C859,Concentrado!$A$2:$A859,"="&$A16,Concentrado!$B$2:$B859, "=Nacional") -> 17.34 | C16: =SUMIFS(Concentrado!D$2:D859,Concentrado!$A$2:$A859,"="&$A16,Concentrado!$B$2:$B859, "=Nacional") -> 4.563 | D16: =SUMIFS(Concentrado!E$2:E859,Concentrado!$A$2:$A859,"="&$A16,Concentrado!$B$2:$B859, "=Nacional") -> 10.826 | E16: =SUMIFS(Concentrado!F$2:F859,Concentrado!$A$2:$A859,"="&$A16,Concentrado!$B$2:$B859, "=Nacional") -> 11.938 | F16: =SUMIFS(Concentrado!G$2:G859,Concentrado!$A$2:$A859,"="&$A16,Concentrado!$B$2:$B859, "=Nacional") -> 17.393 | G16: =SUMIFS(Concentrado!H$2:H859,Concentrado!$A$2:$A859,"="&$A16,Concentrado!$B$2:$B859, "=Nacional") -> 4.312 | H16: =SUMIFS(Concentrado!I$2:I859,Concentrado!$A$2:$A859,"="&$A16,Concentrado!$B$2:$B859, "=Nacional") -> 3.691 | I16: =SUMIFS(Concentrado!J$2:J859,Concentrado!$A$2:$A859,"="&$A16,Concentrado!$B$2:$B859, "=Nacional") -> 3.995 | ... BG16: =SUMIFS(Concentrado!BH$2:BH859,Concentrado!$A$2:$A859,"="&$A16,Concentrado!$B$2:$B859, "=Nacional") -> 7.955407
A17: 2013 | B17: =SUMIFS(Concentrado!C$2:C859,Concentrado!$A$2:$A859,"="&$A17,Concentrado!$B$2:$B859, "=Nacional") -> 15.827 | C17: =SUMIFS(Concentrado!D$2:D859,Concentrado!$A$2:$A859,"="&$A17,Concentrado!$B$2:$B859, "=Nacional") -> 3.867 | D17: =SUMIFS(Concentrado!E$2:E859,Concentrado!$A$2:$A859,"="&$A17,Concentrado!$B$2:$B859, "=Nacional") -> 9.725 | E17: =SUMIFS(Concentrado!F$2:F859,Concentrado!$A$2:$A859,"="&$A17,Concentrado!$B$2:$B859, "=Nacional") -> 11.764 | F17: =SUMIFS(Concentrado!G$2:G859,Concentrado!$A$2:$A859,"="&$A17,Concentrado!$B$2:$B859, "=Nacional") -> 16.811 | G17: =SUMIFS(Concentrado!H$2:H859,Concentrado!$A$2:$A859,"="&$A17,Concentrado!$B$2:$B859, "=Nacional") -> 4.676 | H17: =SUMIFS(Concentrado!I$2:I859,Concentrado!$A$2:$A859,"="&$A17,Concentrado!$B$2:$B859, "=Nacional") -> 4.009 | I17: =SUMIFS(Concentrado!J$2:J859,Concentrado!$A$2:$A859,"="&$A17,Concentrado!$B$2:$B859, "=Nacional") -> 4.335 | ... BG17: =SUMIFS(Concentrado!BH$2:BH859,Concentrado!$A$2:$A859,"="&$A17,Concentrado!$B$2:$B859, "=Nacional") -> 7.4062901
A18: 2014 | B18: =SUMIFS(Concentrado!C$2:C859,Concentrado!$A$2:$A859,"="&$A18,Concentrado!$B$2:$B859, "=Nacional") -> 15.668 | C18: =SUMIFS(Concentrado!D$2:D859,Concentrado!$A$2:$A859,"="&$A18,Concentrado!$B$2:$B859, "=Nacional") -> 3.941 | D18: =SUMIFS(Concentrado!E$2:E859,Concentrado!$A$2:$A859,"="&$A18,Concentrado!$B$2:$B859, "=Nacional") -> 9.69 | E18: =SUMIFS(Concentrado!F$2:F859,Concentrado!$A$2:$A859,"="&$A18,Concentrado!$B$2:$B859, "=Nacional") -> 12.059 | F18: =SUMIFS(Concentrado!G$2:G859,Concentrado!$A$2:$A859,"="&$A18,Concentrado!$B$2:$B859, "=Nacional") -> 17.762 | G18: =SUMIFS(Concentrado!H$2:H859,Concentrado!$A$2:$A859,"="&$A18,Concentrado!$B$2:$B859, "=Nacional") -> 4.776 | H18: =SUMIFS(Concentrado!I$2:I859,Concentrado!$A$2:$A859,"="&$A18,Concentrado!$B$2:$B859, "=Nacional") -> 4.158 | I18: =SUMIFS(Concentrado!J$2:J859,Concentrado!$A$2:$A859,"="&$A18,Concentrado!$B$2:$B859, "=Nacional") -> 4.46 | ... BG18: =SUMIFS(Concentrado!BH$2:BH859,Concentrado!$A$2:$A859,"="&$A18,Concentrado!$B$2:$B859, "=Nacional") -> 7.3700887
A19: 2015 | B19: =SUMIFS(Concentrado!C$2:C859,Concentrado!$A$2:$A859,"="&$A19,Concentrado!$B$2:$B859, "=Nacional") -> 15.176 | C19: =SUMIFS(Concentrado!D$2:D859,Concentrado!$A$2:$A859,"="&$A19,Concentrado!$B$2:$B859, "=Nacional") -> 3.883 | D19: =SUMIFS(Concentrado!E$2:E859,Concentrado!$A$2:$A859,"="&$A19,Concentrado!$B$2:$B859, "=Nacional") -> 9.419 | E19: =SUMIFS(Concentrado!F$2:F859,Concentrado!$A$2:$A859,"="&$A19,Concentrado!$B$2:$B859, "=Nacional") -> 11.618 | F19: =SUMIFS(Concentrado!G$2:G859,Concentrado!$A$2:$A859,"="&$A19,Concentrado!$B$2:$B859, "=Nacional") -> 18.187 | G19: =SUMIFS(Concentrado!H$2:H859,Concentrado!$A$2:$A859,"="&$A19,Concentrado!$B$2:$B859, "=Nacional") -> 5.126 | H19: =SUMIFS(Concentrado!I$2:I859,Concentrado!$A$2:$A859,"="&$A19,Concentrado!$B$2:$B859, "=Nacional") -> 4.444 | I19: =SUMIFS(Concentrado!J$2:J859,Concentrado!$A$2:$A859,"="&$A19,Concentrado!$B$2:$B859, "=Nacional") -> 4.777 | ... BG19: =SUMIFS(Concentrado!BH$2:BH859,Concentrado!$A$2:$A859,"="&$A19,Concentrado!$B$2:$B859, "=Nacional") -> 7.4180129
A20: 2016 | B20: =SUMIFS(Concentrado!C$2:C859,Concentrado!$A$2:$A859,"="&$A20,Concentrado!$B$2:$B859, "=Nacional") -> 15.054 | C20: =SUMIFS(Concentrado!D$2:D859,Concentrado!$A$2:$A859,"="&$A20,Concentrado!$B$2:$B859, "=Nacional") -> 3.673 | D20: =SUMIFS(Concentrado!E$2:E859,Concentrado!$A$2:$A859,"="&$A20,Concentrado!$B$2:$B859, "=Nacional") -> 9.255 | E20: =SUMIFS(Concentrado!F$2:F859,Concentrado!$A$2:$A859,"="&$A20,Concentrado!$B$2:$B859, "=Nacional") -> 11.536 | F20: =SUMIFS(Concentrado!G$2:G859,Concentrado!$A$2:$A859,"="&$A20,Concentrado!$B$2:$B859, "=Nacional") -> 18.882 | G20: =SUMIFS(Concentrado!H$2:H859,Concentrado!$A$2:$A859,"="&$A20,Concentrado!$B$2:$B859, "=Nacional") -> 5.337 | H20: =SUMIFS(Concentrado!I$2:I859,Concentrado!$A$2:$A859,"="&$A20,Concentrado!$B$2:$B859, "=Nacional") -> 4.461 | I20: =SUMIFS(Concentrado!J$2:J859,Concentrado!$A$2:$A859,"="&$A20,Concentrado!$B$2:$B859, "=Nacional") -> 4.89 | ... BG20: =SUMIFS(Concentrado!BH$2:BH859,Concentrado!$A$2:$A859,"="&$A20,Concentrado!$B$2:$B859, "=Nacional") -> 7.1503262
A21: 2017 | B21: =SUMIFS(Concentrado!C$2:C859,Concentrado!$A$2:$A859,"="&$A21,Concentrado!$B$2:$B859, "=Nacional") -> 14.098 | C21: =SUMIFS(Concentrado!D$2:D859,Concentrado!$A$2:$A859,"="&$A21,Concentrado!$B$2:$B859, "=Nacional") -> 3.403 | D21: =SUMIFS(Concentrado!E$2:E859,Concentrado!$A$2:$A859,"="&$A21,Concentrado!$B$2:$B859, "=Nacional") -> 8.641 | E21: =SUMIFS(Concentrado!F$2:F859,Concentrado!$A$2:$A859,"="&$A21,Concentrado!$B$2:$B859, "=Nacional") -> 11.245 | F21: =SUMIFS(Concentrado!G$2:G859,Concentrado!$A$2:$A859,"="&$A21,Concentrado!$B$2:$B859, "=Nacional") -> 19.009 | G21: =SUMIFS(Concentrado!H$2:H859,Concentrado!$A$2:$A859,"="&$A21,Concentrado!$B$2:$B859, "=Nacional") -> 5.672 | H21: =SUMIFS(Concentrado!I$2:I859,Concentrado!$A$2:$A859,"="&$A21,Concentrado!$B$2:$B859, "=Nacional") -> 4.708 | I21: =SUMIFS(Concentrado!J$2:J859,Concentrado!$A$2:$A859,"="&$A21,Concentrado!$B$2:$B859, "=Nacional") -> 5.18 | ... BG21: =SUMIFS(Concentrado!BH$2:BH859,Concentrado!$A$2:$A859,"="&$A21,Concentrado!$B$2:$B859, "=Nacional") -> 7.3919185
A22: 2018 | B22: =SUMIFS(Concentrado!C$2:C859,Concentrado!$A$2:$A859,"="&$A22,Concentrado!$B$2:$B859, "=Nacional") -> 13.622 | C22: =SUMIFS(Concentrado!D$2:D859,Concentrado!$A$2:$A859,"="&$A22,Concentrado!$B$2:$B859, "=Nacional") -> 3.298 | D22: =SUMIFS(Concentrado!E$2:E859,Concentrado!$A$2:$A859,"="&$A22,Concentrado!$B$2:$B859, "=Nacional") -> 8.354 | E22: =SUMIFS(Concentrado!F$2:F859,Concentrado!$A$2:$A859,"="&$A22,Concentrado!$B$2:$B859, "=Nacional") -> 11.186 | F22: =SUMIFS(Concentrado!G$2:G859,Concentrado!$A$2:$A859,"="&$A22,Concentrado!$B$2:$B859, "=Nacional") -> 19.61 | G22: =SUMIFS(Concentrado!H$2:H859,Concentrado!$A$2:$A859,"="&$A22,Concentrado!$B$2:$B859, "=Nacional") -> 5.654 | H22: =SUMIFS(Concentrado!I$2:I859,Concentrado!$A$2:$A859,"="&$A22,Concentrado!$B$2:$B859, "=Nacional") -> 4.696 | I22: =SUMIFS(Concentrado!J$2:J859,Concentrado!$A$2:$A859,"="&$A22,Concentrado!$B$2:$B859, "=Nacional") -> 5.165 | ... BG22: =SUMIFS(Concentrado!BH$2:BH859,Concentrado!$A$2:$A859,"="&$A22,Concentrado!$B$2:$B859, "=Nacional") -> 7.3112783
A23: 2019 | B23: =SUMIFS(Concentrado!C$2:C859,Concentrado!$A$2:$A859,"="&$A23,Concentrado!$B$2:$B859, "=Nacional") -> 13.051 | C23: =SUMIFS(Concentrado!D$2:D859,Concentrado!$A$2:$A859,"="&$A23,Concentrado!$B$2:$B859, "=Nacional") -> 3.2 | D23: =SUMIFS(Concentrado!E$2:E859,Concentrado!$A$2:$A859,"="&$A23,Concentrado!$B$2:$B859, "=Nacional") -> 8.026 | E23: =SUMIFS(Concentrado!F$2:F859,Concentrado!$A$2:$A859,"="&$A23,Concentrado!$B$2:$B859, "=Nacional") -> 10.688 | F23: =SUMIFS(Concentrado!G$2:G859,Concentrado!$A$2:$A859,"="&$A23,Concentrado!$B$2:$B859, "=Nacional") -> 19.976 | G23: =SUMIFS(Concentrado!H$2:H859,Concentrado!$A$2:$A859,"="&$A23,Concentrado!$B$2:$B859, "=Nacional") -> 6.134 | H23: =SUMIFS(Concentrado!I$2:I859,Concentrado!$A$2:$A859,"="&$A23,Concentrado!$B$2:$B859, "=Nacional") -> 4.956 | I23: =SUMIFS(Concentrado!J$2:J859,Concentrado!$A$2:$A859,"="&$A23,Concentrado!$B$2:$B859, "=Nacional") -> 5.533 | ... BG23: =SUMIFS(Concentrado!BH$2:BH859,Concentrado!$A$2:$A859,"="&$A23,Concentrado!$B$2:$B859, "=Nacional") -> 7.2317411
A24: 2020 | B24: =SUMIFS(Concentrado!C$2:C859,Concentrado!$A$2:$A859,"="&$A24,Concentrado!$B$2:$B859, "=Nacional") -> 12.419 | C24: =SUMIFS(Concentrado!D$2:D859,Concentrado!$A$2:$A859,"="&$A24,Concentrado!$B$2:$B859, "=Nacional") -> 2.636 | D24: =SUMIFS(Concentrado!E$2:E859,Concentrado!$A$2:$A859,"="&$A24,Concentrado!$B$2:$B859, "=Nacional") -> 7.426 | E24: =SUMIFS(Concentrado!F$2:F859,Concentrado!$A$2:$A859,"="&$A24,Concentrado!$B$2:$B859, "=Nacional") -> 11.008 | F24: =SUMIFS(Concentrado!G$2:G859,Concentrado!$A$2:$A859,"="&$A24,Concentrado!$B$2:$B859, "=Nacional") -> 20.477 | G24: =SUMIFS(Concentrado!H$2:H859,Concentrado!$A$2:$A859,"="&$A24,Concentrado!$B$2:$B859, "=Nacional") -> 6.469 | H24: =SUMIFS(Concentrado!I$2:I859,Concentrado!$A$2:$A859,"="&$A24,Concentrado!$B$2:$B859, "=Nacional") -> 5.096 | I24: =SUMIFS(Concentrado!J$2:J859,Concentrado!$A$2:$A859,"="&$A24,Concentrado!$B$2:$B859, "=Nacional") -> 5.768 | ... BG24: =SUMIFS(Concentrado!BH$2:BH859,Concentrado!$A$2:$A859,"="&$A24,Concentrado!$B$2:$B859, "=Nacional") -> 6.7593769
A25: 2021 | B25: =SUMIFS(Concentrado!C$2:C859,Concentrado!$A$2:$A859,"="&$A25,Concentrado!$B$2:$B859, "=Nacional") -> 12.897 | C25: =SUMIFS(Concentrado!D$2:D859,Concentrado!$A$2:$A859,"="&$A25,Concentrado!$B$2:$B859, "=Nacional") -> 2.967 | D25: =SUMIFS(Concentrado!E$2:E859,Concentrado!$A$2:$A859,"="&$A25,Concentrado!$B$2:$B859, "=Nacional") -> 7.826 | E25: =SUMIFS(Concentrado!F$2:F859,Concentrado!$A$2:$A859,"="&$A25,Concentrado!$B$2:$B859, "=Nacional") -> 10.919 | F25: =SUMIFS(Concentrado!G$2:G859,Concentrado!$A$2:$A859,"="&$A25,Concentrado!$B$2:$B859, "=Nacional") -> 20.325 | G25: =SUMIFS(Concentrado!H$2:H859,Concentrado!$A$2:$A859,"="&$A25,Concentrado!$B$2:$B859, "=Nacional") -> 6.584 | H25: =SUMIFS(Concentrado!I$2:I859,Concentrado!$A$2:$A859,"="&$A25,Concentrado!$B$2:$B859, "=Nacional") -> 5.429 | I25: =SUMIFS(Concentrado!J$2:J859,Concentrado!$A$2:$A859,"="&$A25,Concentrado!$B$2:$B859, "=Nacional") -> 5.994 | ... BG25: =SUMIFS(Concentrado!BH$2:BH859,Concentrado!$A$2:$A859,"="&$A25,Concentrado!$B$2:$B859, "=Nacional") -> 6.7951367
A26: 2022 | B26: =SUMIFS(Concentrado!C$2:C859,Concentrado!$A$2:$A859,"="&$A26,Concentrado!$B$2:$B859, "=Nacional") -> 13.941 | C26: =SUMIFS(Concentrado!D$2:D859,Concentrado!$A$2:$A859,"="&$A26,Concentrado!$B$2:$B859, "=Nacional") -> 3.531 | D26: =SUMIFS(Concentrado!E$2:E859,Concentrado!$A$2:$A859,"="&$A26,Concentrado!$B$2:$B859, "=Nacional") -> 8.628 | E26: =SUMIFS(Concentrado!F$2:F859,Concentrado!$A$2:$A859,"="&$A26,Concentrado!$B$2:$B859, "=Nacional") -> 10.759 | F26: =SUMIFS(Concentrado!G$2:G859,Concentrado!$A$2:$A859,"="&$A26,Concentrado!$B$2:$B859, "=Nacional") -> 19.793 | G26: =SUMIFS(Concentrado!H$2:H859,Concentrado!$A$2:$A859,"="&$A26,Concentrado!$B$2:$B859, "=Nacional") -> 6.568 | H26: =SUMIFS(Concentrado!I$2:I859,Concentrado!$A$2:$A859,"="&$A26,Concentrado!$B$2:$B859, "=Nacional") -> 5.356 | I26: =SUMIFS(Concentrado!J$2:J859,Concentrado!$A$2:$A859,"="&$A26,Concentrado!$B$2:$B859, "=Nacional") -> 5.949 | ... BG26: =SUMIFS(Concentrado!BH$2:BH859,Concentrado!$A$2:$A859,"="&$A26,Concentrado!$B$2:$B859, "=Nacional") -> 7.0319866
A27: 2023 | B27: =SUMIFS(Concentrado!C$2:C859,Concentrado!$A$2:$A859,"="&$A27,Concentrado!$B$2:$B859, "=Nacional") -> 14.781 | C27: =SUMIFS(Concentrado!D$2:D859,Concentrado!$A$2:$A859,"="&$A27,Concentrado!$B$2:$B859, "=Nacional") -> 3.573 | D27: =SUMIFS(Concentrado!E$2:E859,Concentrado!$A$2:$A859,"="&$A27,Concentrado!$B$2:$B859, "=Nacional") -> 9.06 | E27: =SUMIFS(Concentrado!F$2:F859,Concentrado!$A$2:$A859,"="&$A27,Concentrado!$B$2:$B859, "=Nacional") -> 11.206 | F27: =SUMIFS(Concentrado!G$2:G859,Concentrado!$A$2:$A859,"="&$A27,Concentrado!$B$2:$B859, "=Nacional") -> 19.871 | G27: =SUMIFS(Concentrado!H$2:H859,Concentrado!$A$2:$A859,"="&$A27,Concentrado!$B$2:$B859, "=Nacional") -> 6.634 | H27: =SUMIFS(Concentrado!I$2:I859,Concentrado!$A$2:$A859,"="&$A27,Concentrado!$B$2:$B859, "=Nacional") -> 5.593 | I27: =SUMIFS(Concentrado!J$2:J859,Concentrado!$A$2:$A859,"="&$A27,Concentrado!$B$2:$B859, "=Nacional") -> 6.102 | ... BG27: =SUMIFS(Concentrado!BH$2:BH859,Concentrado!$A$2:$A859,"="&$A27,Concentrado!$B$2:$B859, "=Nacional") -> 8.3675665

Sheet AGS
